Executing <Task pending name='Task-2' coro=<run_server() running at /mnt/c/Users/Rayman/Desktop/l3_data_collection/src/ws_disseminator/server_daemon.py:39> wait_for=<_GatheringFuture pending cb=[<TaskWakeupMethWrapper object at 0x7feb6abe7b80>()] created at /usr/lib/python3.9/asyncio/tasks.py:704> created at /usr/lib/python3.9/asyncio/tasks.py:361> took 0.124 seconds
connection handler failed
Traceback (most recent call last):
  File "/mnt/c/Users/Rayman/Desktop/l3_data_collection/src/ws_disseminator/client_handler.py", line 53, in handle_ws
    done, pending = await asyncio.wait(
  File "/usr/lib/python3.9/asyncio/tasks.py", line 413, in wait
    return await _wait(fs, timeout, return_when, loop)
  File "/usr/lib/python3.9/asyncio/tasks.py", line 529, in _wait
    await waiter
asyncio.exceptions.CancelledError

During handling of the above exception, another exception occurred:

Traceback (most recent call last):
  File "/home/raymant/.local/lib/python3.9/site-packages/websockets/legacy/server.py", line 231, in handler
    await self.ws_handler(self)
  File "/mnt/c/Users/Rayman/Desktop/l3_data_collection/src/ws_disseminator/client_handler.py", line 63, in handle_ws
    await client.shutdown()
  File "/mnt/c/Users/Rayman/Desktop/l3_data_collection/src/ws_disseminator/client_handler.py", line 38, in shutdown
    await self.ws.close()
  File "/home/raymant/.local/lib/python3.9/site-packages/websockets/legacy/protocol.py", line 749, in close
    await asyncio.wait_for(
  File "/usr/lib/python3.9/asyncio/tasks.py", line 481, in wait_for
    return fut.result()
  File "/home/raymant/.local/lib/python3.9/site-packages/websockets/legacy/protocol.py", line 1215, in write_close_frame
    await self.write_frame(True, OP_CLOSE, data, _state=State.CLOSING)
  File "/home/raymant/.local/lib/python3.9/site-packages/websockets/legacy/protocol.py", line 1187, in write_frame
    self.write_frame_sync(fin, opcode, data)
  File "/home/raymant/.local/lib/python3.9/site-packages/websockets/legacy/protocol.py", line 1158, in write_frame_sync
    frame.write(
  File "/home/raymant/.local/lib/python3.9/site-packages/websockets/legacy/framing.py", line 146, in write
    write(self.new_frame.serialize(mask=mask, extensions=extensions))
  File "/usr/lib/python3.9/asyncio/selector_events.py", line 903, in write
    raise RuntimeError('Cannot call write() after write_eof()')
RuntimeError: Cannot call write() after write_eof()
